Workbook
Name ST2.0MapDeliveryVariants: '[1]Map Cut'!$G$52:$G$72

Sheet Variants
A1: Variants | D1: x | E1: x | F1: x | I1: x | M1: x | N1: x | O1: x | P1: x | Q1: (x) | R1: x | S1: (x) | T1: x | U1: TBD | V1: x | W1: x | X1: x | Y1: x | Z1: x
A2: 1 | B2: 2 | C2: 3 | D2: 4 | E2: 5 | F2: 6 | G2: 7 | H2: 8 | I2: 9 | J2: 10 | K2: 11 | L2: 12 | M2: 13 | N2: 14 | O2: 15 | P2: 16 | Q2: 17 | R2: 18 | S2: 19 | T2: 20 | U2: 21 | V2: 22 | W2: 23 | X2: 24 | Y2: 25 | Z2: 25 | AA2: 26 | AB2: 27 | AC2: 28 | AD2: 29 | AE2: 30 | AF2: 31 | AG2: 32 | AH2: 33
A3: SW_Variant_ID / FCID | B3: SW_Variant_ID / FCID (HEX) | C3: Grouping (only naming) | D3: Board ID/DTB | E3: Platform | F3: RFS | G3: RFS (as in Manifest) | H3: China Encoder | I3: Navigation | J3: Customer (fixed by RFS) | K3: Type (fixed by RFS) | L3: HMI (fixed by RFS) | M3: Partitioning Schema 1 (1st eMMC) | N3: Partitioning Schema 2 (2nd eMMC) | O3: SDB Data | P3: Gracenote | Q3: V850 (depends on Board-ID) | R3: ADR_FW_Type | S3: Arkamys (Part of ADR) | T3: SXM | U3: eCore | V3: Map Data (only for production) | W3: GNSS | X3: FPGA (Sub-PCB) CPLD (Fascia) | Y3: CPLD (PORT EXTENDER) | Z3: Serial NOR for Ethernet Switch | AA3: Transferred to PD | AB3: HW-Variant ID ERNIE | AC3: Bosch Partnumber (HW-Index) | AD3: GenCtrl | AE3: Tryout Asset | AF3: Added | AG3: Sample Build | AH3: Comment
A4: 1 | B4: =DEC2HEX(A4,4) -> 0001 | C4: Nissan Scope 0 (Scope 1) EUR | D4: 0682 (DL) | E4: imx | F4: RFS_GEN3_1 | G4: nivic | H4: No_Chenc | I4: No_Navigation | J4: Nissan | K4: DA-Entry | L4: Nissan_HMI_Scope_1.0 | M4: PARTITION_SCHEMA8_NissanScope1 | N4: NO_EMMC | O4: No_SDB | P4: =IF(AND(OR(INDIRECT("K" & ROW())="NAV-Premium",INDIRECT("K" & ROW())="DA-Premium"),INDIRECT("M" & ROW())="PARTITION_SCHEMA128__NavPiviJpn", INDIRECT("O" & ROW())="JPN_SDB"),'SDB vs GN'!$B$41, IF(INDIRECT("H" & ROW())="Chenc",'SDB vs GN'!$B$40, VLOOKUP(INDIRECT("O" & ROW()),'SDB vs GN'!$A$16:$B$38,2,FALSE))) -> No_Gracenote | Q4: V850_Scope_1 | R4: AARS_IVI_S1_NA_FM | S4: No_Arkamys | T4: SXM_not_updatable | U4: No_eCore | V4: No_Map | W4: GNSS_not_updatable | X4: FPGA_and_CPLD_not_updatable | Y4: NO_CPLD_PEXT | Z4: NO_ETH_SWITCH | AB4: 385 531 346 530 | AC4: 7.510.750.804-01 (HW03), 7.510.750.804-97 (HW03), 7.500.750.801-01 ( ' ' ), 7.500.750.801-97 ( ' ' ) | AD4: use | AH4: Separation of FCIDs regarding MID, Entry, DA shall be done in the future if needed. Scope 1 V850 does not work with Teseo. Therefore Teseo can not be updated. Changed in Variant table
A5: 2 | B5: =DEC2HEX(A5,4) -> 0002 | C5: Nissan Scope 0 (Scope 1) EUR | D5: 0681 (DL) | E5: imx | F5: RFS_GEN3_1 | G5: nivic | H5: No_Chenc | I5: No_Navigation | J5: Nissan | K5: DA-Entry | L5: Nissan_HMI_Scope_1.0 | M5: PARTITION_SCHEMA8_NissanScope1 | N5: NO_EMMC | O5: No_SDB | P5: =IF(AND(OR(INDIRECT("K" & ROW())="NAV-Premium",INDIRECT("K" & ROW())="DA-Premium"),INDIRECT("M" & ROW())="PARTITION_SCHEMA128__NavPiviJpn", INDIRECT("O" & ROW())="JPN_SDB"),'SDB vs GN'!$B$41, IF(INDIRECT("H" & ROW())="Chenc",'SDB vs GN'!$B$40, VLOOKUP(INDIRECT("O" & ROW()),'SDB vs GN'!$A$16:$B$38,2,FALSE))) -> No_Gracenote | Q5: V850_Scope_1 | R5: AARS_IVI_S1_NA_FM | S5: No_Arkamys | T5: SXM_not_updatable | U5: No_eCore | V5: No_Map | W5: GNSS_not_updatable | X5: FPGA_and_CPLD_not_updatable | Y5: NO_CPLD_PEXT | Z5: NO_ETH_SWITCH | AB5: 388 352 | AC5: 7.510.750.800-99 (' '), 7.510.750.801-01 ( ' ' ) | AD5: use | AH5: Scope 1 V850 does not work with Teseo. Therefore Teseo can not be updated. Changed in Variant table
A6: 3 | B6: =DEC2HEX(A6,4) -> 0003 | C6: Nissan Scope 0 (Scope 2) EUR FM | D6: 0681 (DL) | E6: imx | F6: RFS_GEN3_2 | G6: rnaivi_nav | H6: No_Chenc | I6: Bosch_Navigation | J6: Nissan | K6: NAV-Entry | L6: Nissan_HMI_Scope_2.0 | M6: PARTITION_SCHEMA16__Nav | N6: NO_EMMC | O6: EUL_SDB | P6: =IF(AND(OR(INDIRECT("K" & ROW())="NAV-Premium",INDIRECT("K" & ROW())="DA-Premium"),INDIRECT("M" & ROW())="PARTITION_SCHEMA128__NavPiviJpn", INDIRECT("O" & ROW())="JPN_SDB"),'SDB vs GN'!$B$41, IF(INDIRECT("H" & ROW())="Chenc",'SDB vs GN'!$B$40, VLOOKUP(INDIRECT("O" & ROW()),'SDB vs GN'!$A$16:$B$38,2,FALSE))) -> 731_EUR | Q6: V850_Scope_1 | R6: AARS_IVI_S1_NA_FM | S6: No_Arkamys | T6: SXM_not_updatable | U6: No_eCore | V6: EUR_ST2.0_N_ENTRY | W6: GNSS_not_updatable | X6: FPGA_and_CPLD_not_updatable | Y6: NO_CPLD_PEXT | Z6: NO_ETH_SWITCH | AD6: use | AH6: Scope 1 V850 does not work with Teseo. Therefore Teseo can not be updated. Changed in Variant table
A7: 4 | B7: =DEC2HEX(A7,4) -> 0004 | C7: Nissan Scope 0 (Scope 2) EUR DAB | D7: 0681 (DL) | E7: imx | F7: RFS_GEN3_2 | G7: rnaivi_nav | H7: No_Chenc | I7: Bosch_Navigation | J7: Nissan | K7: NAV-Entry | L7: Nissan_HMI_Scope_2.0 | M7: PARTITION_SCHEMA16__Nav | N7: NO_EMMC | O7: EUL_SDB | P7: =IF(AND(OR(INDIRECT("K" & ROW())="NAV-Premium",INDIRECT("K" & ROW())="DA-Premium"),INDIRECT("M" & ROW())="PARTITION_SCHEMA128__NavPiviJpn", INDIRECT("O" & ROW())="JPN_SDB"),'SDB vs GN'!$B$41, IF(INDIRECT("H" & ROW())="Chenc",'SDB vs GN'!$B$40, VLOOKUP(INDIRECT("O" & ROW()),'SDB vs GN'!$A$16:$B$38,2,FALSE))) -> 731_EUR | Q7: V850_Scope_1 | R7: AARS_IVI_S0_NA_DAB | S7: No_Arkamys | T7: SXM_not_updatable | U7: No_eCore | V7: EUR_ST2.0_N_ENTRY | W7: GNSS_not_updatable | X7: FPGA_and_CPLD_not_updatable | Y7: NO_CPLD_PEXT | Z7: NO_ETH_SWITCH | AB7: 533 534 | AC7: 7.510.750.800-98 ( ' ' ), 7.510.750.801-98( ' ' ) | AD7: use | AH7: Scope 1 V850 does not work with Teseo. Therefore Teseo can not be updated. Changed in Variant table
A8: 5 | B8: =DEC2HEX(A8,4) -> 0005 | C8: Nissan Scope 0 (Scope 2) NAR | D8: 0681 (DL) | E8: imx | F8: RFS_GEN3_2 | G8: rnaivi_nav | H8: No_Chenc | I8: Bosch_Navigation | J8: Nissan | K8: NAV-Entry | L8: Nissan_HMI_Scope_2.0 | M8: PARTITION_SCHEMA16__Nav | N8: NO_EMMC | O8: NAM_SDB | P8: =IF(AND(OR(INDIRECT("K" & ROW())="NAV-Premium",INDIRECT("K" & ROW())="DA-Premium"),INDIRECT("M" & ROW())="PARTITION_SCHEMA128__NavPiviJpn", INDIRECT("O" & ROW())="JPN_SDB"),'SDB vs GN'!$B$41, IF(INDIRECT("H" & ROW())="Chenc",'SDB vs GN'!$B$40, VLOOKUP(INDIRECT("O" & ROW()),'SDB vs GN'!$A$16:$B$38,2,FALSE))) -> 727_NAM | Q8: V850_Scope_1 | R8: AARS_IVI_S0_NA_HD | S8: No_Arkamys | T8: SXM_updatable | U8: No_eCore | V8: NAM_ST2.0_N_ENTRY | W8: GNSS_not_updatable | X8: FPGA_and_CPLD_not_updatable | Y8: NO_CPLD_PEXT | Z8: NO_ETH_SWITCH | AB8: 389 351 | AC8: 7.510.750.801-99 ( ' ' ), 7.510.750.800-01 ( ' ' ) | AD8: use | AH8: Changed to FCID 5 to support also SDS correctly. In addition ADR set to AARS_IVI_S1_NA_FM in order to have correclty working ADR SW. ADR SW ADR3_IVI_S0_NA_HD is to old. Scope 1 V850 does not work with Teseo. Therefore Teseo can not be updated. Changed in Variant table
A9: 17 | B9: =DEC2HEX(A9,4) -> 0011 | C9: Nissan Scope 1 | D9: 0686 (Single) | E9: imx | F9: RFS_GEN3_1 | G9: nivic | H9: No_Chenc | I9: No_Navigation | J9: Nissan | K9: DA-Entry | L9: Nissan_HMI_Scope_1.0 | M9: PARTITION_SCHEMA8_NissanScope1 | N9: NO_EMMC | O9: No_SDB | P9: =IF(AND(OR(INDIRECT("K" & ROW())="NAV-Premium",INDIRECT("K" & ROW())="DA-Premium"),INDIRECT("M" & ROW())="PARTITION_SCHEMA128__NavPiviJpn", INDIRECT("O" & ROW())="JPN_SDB"),'SDB vs GN'!$B$41, IF(INDIRECT("H" & ROW())="Chenc",'SDB vs GN'!$B$40, VLOOKUP(INDIRECT("O" & ROW()),'SDB vs GN'!$A$16:$B$38,2,FALSE))) -> No_Gracenote | Q9: V850_Scope_1 | R9: AARS_IVI_S1_NA_FM | S9: No_Arkamys | T9: SXM_not_updatable | U9: No_eCore | V9: No_Map | W9: GNSS_not_updatable | X9: FPGA_and_CPLD_not_updatable | Y9: NO_CPLD_PEXT | Z9: NO_ETH_SWITCH | AB9: 386 386 377 350 429 436 | AC9: 7.510.750.804-01 (HW04), 7.510.750.804-97 (HW04), 7.503.750.804-01 (HW05), 7.503.750.801-01 (HW05), 7.503.750.804-02 (HW05), 7.503.750.801-02 (HW05) | AD9: use | AH9: 7.505.750806-03
A10: 6 | B10: =DEC2HEX(A10,4) -> 0006 | C10: Nissan Scope 1 (Miyata edition) | D10: 0685 (Single) | E10: imx | F10: RFS_GEN3_1 | G10: nivic | H10: No_Chenc | I10: No_Navigation | J10: Nissan | K10: DA-Entry | L10: Nissan_HMI_Scope_1.0 | M10: PARTITION_SCHEMA8_NissanScope1 | N10: NO_EMMC | O10: No_SDB | P10: =IF(AND(OR(INDIRECT("K" & ROW())="NAV-Premium",INDIRECT("K" & ROW())="DA-Premium"),INDIRECT("M" & ROW())="PARTITION_SCHEMA128__NavPiviJpn", INDIRECT("O" & ROW())="JPN_SDB"),'SDB vs GN'!$B$41, IF(INDIRECT("H" & ROW())="Chenc",'SDB vs GN'!$B$40, VLOOKUP(INDIRECT("O" & ROW()),'SDB vs GN'!$A$16:$B$38,2,FALSE))) -> No_Gracenote | Q10: V850_Scope_1 | R10: AARS_IVI_S1_NA_FM | S10: No_Arkamys | T10: SXM_not_updatable | U10: No_eCore | V10: No_Map | W10: GNSS_not_updatable | X10: FPGA_and_CPLD_not_updatable | Y10: NO_CPLD_PEXT | Z10: NO_ETH_SWITCH | AD10: use
A11: 7 | B11: =DEC2HEX(A11,4) -> 0007 | C11: Nissan Scope 2 MID Navi NAR (HD) | D11: 0683 (DL) | E11: imx | F11: RFS_GEN3_2 | G11: rnaivi_nav | H11: No_Chenc | I11: Bosch_Navigation | J11: Nissan | K11: NAV-Mid | L11: Nissan_HMI_Scope_2.0 | M11: PARTITION_SCHEMA32__NavSmallSdb | N11: NO_EMMC | O11: NAM_SDB | P11: =IF(AND(OR(INDIRECT("K" & ROW())="NAV-Premium",INDIRECT("K" & ROW())="DA-Premium"),INDIRECT("M" & ROW())="PARTITION_SCHEMA128__NavPiviJpn", INDIRECT("O" & ROW())="JPN_SDB"),'SDB vs GN'!$B$41, IF(INDIRECT("H" & ROW())="Chenc",'SDB vs GN'!$B$40, VLOOKUP(INDIRECT("O" & ROW()),'SDB vs GN'!$A$16:$B$38,2,FALSE))) -> 727_NAM | Q11: V850_Scope_2 | R11: AARS_IVI_S2_AC_HD | S11: Arkamys_Classic | T11: SXM_updatable | U11: No_eCore | V11: NAM_ST2.0_N_MID | W11: Teseo_2_updatable | X11: FPGA_and_CPLD_not_updatable | Y11: NO_CPLD_PEXT | Z11: NO_ETH_SWITCH | AB11: 353 355 | AC11: 7.510.750.827-01, 7.510.750.805-01 (HW02;HW03) | AD11: use
A12: 8 | B12: =DEC2HEX(A12,4) -> 0008 | C12: Nissan Scope 2 MID Navi NAR (FM) | D12: 0683 (DL) | E12: imx | F12: RFS_GEN3_2 | G12: rnaivi_nav | H12: No_Chenc | I12: Bosch_Navigation | J12: Nissan | K12: NAV-Mid | L12: Nissan_HMI_Scope_2.0 | M12: PARTITION_SCHEMA32__NavSmallSdb | N12: NO_EMMC | O12: NAM_SDB | P12: =IF(AND(OR(INDIRECT("K" & ROW())="NAV-Premium",INDIRECT("K" & ROW())="DA-Premium"),INDIRECT("M" & ROW())="PARTITION_SCHEMA128__NavPiviJpn", INDIRECT("O" & ROW())="JPN_SDB"),'SDB vs GN'!$B$41, IF(INDIRECT("H" & ROW())="Chenc",'SDB vs GN'!$B$40, VLOOKUP(INDIRECT("O" & ROW()),'SDB vs GN'!$A$16:$B$38,2,FALSE))) -> 727_NAM | Q12: V850_Scope_2 | R12: AARS_IVI_S2_AC_FM | S12: Arkamys_Classic | T12: SXM_updatable | U12: No_eCore | V12: NAM_ST2.0_N_MID | W12: Teseo_2_updatable | X12: FPGA_and_CPLD_not_updatable | Y12: NO_CPLD_PEXT | Z12: NO_ETH_SWITCH | AD12: use
A13: 9 | B13: =DEC2HEX(A13,4) -> 0009 | C13: Nissan Scope 2 MID Navi NAR (MEX) | D13: 0683 (DL) | E13: imx | F13: RFS_GEN3_2 | G13: rnaivi_nav | H13: No_Chenc | I13: Bosch_Navigation | J13: Nissan | K13: NAV-Mid | L13: Nissan_HMI_Scope_2.0 | M13: PARTITION_SCHEMA32__NavSmallSdb | N13: NO_EMMC | O13: NAM_SDB | P13: =IF(AND(OR(INDIRECT("K" & ROW())="NAV-Premium",INDIRECT("K" & ROW())="DA-Premium"),INDIRECT("M" & ROW())="PARTITION_SCHEMA128__NavPiviJpn", INDIRECT("O" & ROW())="JPN_SDB"),'SDB vs GN'!$B$41, IF(INDIRECT("H" & ROW())="Chenc",'SDB vs GN'!$B$40, VLOOKUP(INDIRECT("O" & ROW()),'SDB vs GN'!$A$16:$B$38,2,FALSE))) -> 727_NAM | Q13: V850_Scope_2 | R13: AARS_IVI_S2_AC_FM | S13: Arkamys_Classic | T13: SXM_not_updatable | U13: No_eCore | V13: NAMEX_ST2.0_N_MID | W13: Teseo_2_updatable | X13: FPGA_and_CPLD_not_updatable | Y13: NO_CPLD_PEXT | Z13: NO_ETH_SWITCH | AD13: use
A14: 10 | B14: =DEC2HEX(A14,4) -> 000A | C14: Nissan Scope 2 MID Navi EUR (DAB) | D14: 0683 (DL) | E14: imx | F14: RFS_GEN3_2 | G14: rnaivi_nav | H14: No_Chenc | I14: Bosch_Navigation | J14: Nissan | K14: NAV-Mid | L14: Nissan_HMI_Scope_2.0 | M14: PARTITION_SCHEMA32__NavLargeSdb | N14: NO_EMMC | O14: EUR_SDB | P14: =IF(AND(OR(INDIRECT("K" & ROW())="NAV-Premium",INDIRECT("K" & ROW())="DA-Premium"),INDIRECT("M" & ROW())="PARTITION_SCHEMA128__NavPiviJpn", INDIRECT("O" & ROW())="JPN_SDB"),'SDB vs GN'!$B$41, IF(INDIRECT("H" & ROW())="Chenc",'SDB vs GN'!$B$40, VLOOKUP(INDIRECT("O" & ROW()),'SDB vs GN'!$A$16:$B$38,2,FALSE))) -> 731_EUR | Q14: V850_Scope_2 | R14: AARS_IVI_S2_AC_DAB | S14: Arkamys_Classic | T14: SXM_not_updatable | U14: No_eCore | V14: EUR_ST2.0_N_MID | W14: Teseo_2_updatable | X14: FPGA_and_CPLD_not_updatable | Y14: NO_CPLD_PEXT | Z14: NO_ETH_SWITCH | AB14: 356, 383 | AC14: 7.510.750.803-01 (HW02;HW03) | AD14: use
A15: 11 | B15: =DEC2HEX(A15,4) -> 000B | C15: Nissan Scope 2 NAV-Mid JPN(JPN) (DARC) | D15: 0684 (Quad) | E15: imx | F15: RFS_GEN3_2J | G15: rnaivi_nav_jpn | H15: No_Chenc | I15: Japan_Navigation | J15: Nissan | K15: NAV-Mid | L15: Nissan_HMI_Scope_2.0 | M15: PARTITION_SCHEMA32__NavSmallSdb | N15: NO_EMMC | O15: JPN_SDB | P15: =IF(AND(OR(INDIRECT("K" & ROW())="NAV-Premium",INDIRECT("K" & ROW())="DA-Premium"),INDIRECT("M" & ROW())="PARTITION_SCHEMA128__NavPiviJpn", INDIRECT("O" & ROW())="JPN_SDB"),'SDB vs GN'!$B$41, IF(INDIRECT("H" & ROW())="Chenc",'SDB vs GN'!$B$40, VLOOKUP(INDIRECT("O" & ROW()),'SDB vs GN'!$A$16:$B$38,2,FALSE))) -> 742_JPN_831_AUSKRJPN | Q15: V850_Scope_2 | R15: AARS_IVI_S2_AC_DARC | S15: Arkamys_Classic | T15: SXM_not_updatable | U15: No_eCore | V15: Japan (ST2.0_N_MID) | W15: Teseo_2_updatable | X15: FPGA_and_CPLD_not_updatable | Y15: NO_CPLD_PEXT | Z15: NO_ETH_SWITCH | AD15: block
A16: 12 | B16: =DEC2HEX(A16,4) -> 000C | C16: Nissan Scope 2 DA-MID NAR (HD) | D16: ??? (Single) | E16: imx | F16: RFS_GEN3_3 | G16: rnaivi_da | H16: No_Chenc | I16: No_Navigation | J16: Nissan | K16: DA-Mid | L16: Nissan_HMI_Scope_2.0 | M16: PARTITION_SCHEMA8__DASdb | N16: NO_EMMC | O16: NAM_SDB | P16: =IF(AND(OR(INDIRECT("K" & ROW())="NAV-Premium",INDIRECT("K" & ROW())="DA-Premium"),INDIRECT("M" & ROW())="PARTITION_SCHEMA128__NavPiviJpn", INDIRECT("O" & ROW())="JPN_SDB"),'SDB vs GN'!$B$41, IF(INDIRECT("H" & ROW())="Chenc",'SDB vs GN'!$B$40, VLOOKUP(INDIRECT("O" & ROW()),'SDB vs GN'!$A$16:$B$38,2,FALSE))) -> 727_NAM | Q16: V850_Scope_2 | R16: AARS_IVI_S2_AC_HD | S16: Arkamys_Classic | T16: SXM_updatable | U16: No_eCore | V16: No_Map | W16: GNSS_not_updatable | X16: FPGA_and_CPLD_not_updatable | Y16: NO_CPLD_PEXT | Z16: NO_ETH_SWITCH | AD16: use
A17: 13 | B17: =DEC2HEX(A17,4) -> 000D | C17: DevSample Nissan Scope 2 MID Navi EUR (DAB) | D17: 0684 (Quad) | E17: imx | F17: RFS_GEN3_2 | G17: rnaivi_nav | H17: No_Chenc | I17: Bosch_Navigation | J17: Nissan | K17: NAV-Mid | L17: Nissan_HMI_Scope_2.0 | M17: PARTITION_SCHEMA64__NavRenault | N17: NO_EMMC | O17: EUR_SDB | P17: =IF(AND(OR(INDIRECT("K" & ROW())="NAV-Premium",INDIRECT("K" & ROW())="DA-Premium"),INDIRECT("M" & ROW())="PARTITION_SCHEMA128__NavPiviJpn", INDIRECT("O" & ROW())="JPN_SDB"),'SDB vs GN'!$B$41, IF(INDIRECT("H" & ROW())="Chenc",'SDB vs GN'!$B$40, VLOOKUP(INDIRECT("O" & ROW()),'SDB vs GN'!$A$16:$B$38,2,FALSE))) -> 731_EUR | Q17: V850_Scope_2 | R17: AARS_IVI_S2_AC_DAB | S17: Arkamys_Classic | T17: SXM_not_updatable | U17: No_eCore | V17: EUR_ST2.0_N_MID | W17: Teseo_2_updatable | X17: FPGA_and_CPLD_not_updatable | Y17: NO_CPLD_PEXT | Z17: NO_ETH_SWITCH | AB17: 384 | AC17: 7.510.750.828-01 (HW03) | AD17: use | AF17: would repart
A18: 14 | B18: =DEC2HEX(A18,4) -> 000E | C18: Nissan Scope 2 MID Navi EUR (AMFM) | D18: ??? (Quad) | E18: imx | F18: RFS_GEN3_2 | G18: rnaivi_nav | H18: No_Chenc | I18: Bosch_Navigation | J18: Nissan | K18: NAV-Mid | L18: Nissan_HMI_Scope_2.0 | M18: PARTITION_SCHEMA32__NavLargeSdb | N18: NO_EMMC | O18: EUR_SDB | P18: =IF(AND(OR(INDIRECT("K" & ROW())="NAV-Premium",INDIRECT("K" & ROW())="DA-Premium"),INDIRECT("M" & ROW())="PARTITION_SCHEMA128__NavPiviJpn", INDIRECT("O" & ROW())="JPN_SDB"),'SDB vs GN'!$B$41, IF(INDIRECT("H" & ROW())="Chenc",'SDB vs GN'!$B$40, VLOOKUP(INDIRECT("O" & ROW()),'SDB vs GN'!$A$16:$B$38,2,FALSE))) -> 731_EUR | Q18: V850_Scope_2 | R18: AARS_IVI_S2_AC_FM | S18: Arkamys_Classic | T18: SXM_not_updatable | U18: No_eCore | V18: EUR_ST2.0_N_MID | W18: Teseo_2_updatable | X18: FPGA_and_CPLD_not_updatable | Y18: NO_CPLD_PEXT | Z18: NO_ETH_SWITCH | AD18: use | AH18: Changed grouping name to Nissan, but anyway there is no corresponding part at the moment.
A19: 15 | B19: =DEC2HEX(A19,4) -> 000F | C19: B-Sample: Nissan Scope 2 MID Navi EUR (DAB) | D19: 0689 (DL) | E19: imx | F19: RFS_GEN3_2 | G19: rnaivi_nav | H19: No_Chenc | I19: Bosch_Navigation | J19: Nissan | K19: NAV-Mid | L19: Nissan_HMI_Scope_2.0 | M19: PARTITION_SCHEMA32__NavLargeSdb | N19: NO_EMMC | O19: EUR_SDB | P19: =IF(AND(OR(INDIRECT("K" & ROW())="NAV-Premium",INDIRECT("K" & ROW())="DA-Premium"),INDIRECT("M" & ROW())="PARTITION_SCHEMA128__NavPiviJpn", INDIRECT("O" & ROW())="JPN_SDB"),'SDB vs GN'!$B$41, IF(INDIRECT("H" & ROW())="Chenc",'SDB vs GN'!$B$40, VLOOKUP(INDIRECT("O" & ROW()),'SDB vs GN'!$A$16:$B$38,2,FALSE))) -> 731_EUR | Q19: V850_Scope_2 | R19: AARS_IVI_S2_AC_DAB | S19: Arkamys_Classic | T19: SXM_not_updatable | U19: No_eCore | V19: EUR_ST2.0_N_MID | W19: Teseo_2_updatable | X19: FPGA_and_CPLD_not_updatable | Y19: NO_CPLD_PEXT | Z19: NO_ETH_SWITCH | AB19: 361 365 360 | AC19: 7.510.750.835-01, 7.510.750.812-01, 7.510.750.809-01 | AD19: use | AH19: [06.06.16] 0x689 = Teseo 2 (checked OK)
A20: 16 | B20: =DEC2HEX(A20,4) -> 0010 | C20: B-Sample: Nissan Scope 2 MID Navi NAR (HD) | D20: 0689 (DL) | E20: imx | F20: RFS_GEN3_2 | G20: rnaivi_nav | H20: No_Chenc | I20: Bosch_Navigation | J20: Nissan | K20: NAV-Mid | L20: Nissan_HMI_Scope_2.0 | M20: PARTITION_SCHEMA32__NavSmallSdb | N20: NO_EMMC | O20: NAM_SDB | P20: =IF(AND(OR(INDIRECT("K" & ROW())="NAV-Premium",INDIRECT("K" & ROW())="DA-Premium"),INDIRECT("M" & ROW())="PARTITION_SCHEMA128__NavPiviJpn", INDIRECT("O" & ROW())="JPN_SDB"),'SDB vs GN'!$B$41, IF(INDIRECT("H" & ROW())="Chenc",'SDB vs GN'!$B$40, VLOOKUP(INDIRECT("O" & ROW()),'SDB vs GN'!$A$16:$B$38,2,FALSE))) -> 727_NAM | Q20: V850_Scope_2 | R20: AARS_IVI_S2_AC_HD | S20: Arkamys_Classic | T20: SXM_updatable | U20: No_eCore | V20: NAM_ST2.0_N_MID | W20: Teseo_2_updatable | X20: FPGA_and_CPLD_not_updatable | Y20: NO_CPLD_PEXT | Z20: NO_ETH_SWITCH | AB20: 364 362 363 359 | AC20: 7.510.750.838-01, 7.510.750.836-01, 7.510.750.811-01, 7.510.750.810-01 | AD20: use | AH20: [06.06.16] 0x689 = Teseo 2 (checked OK)
A21: 18 | B21: =DEC2HEX(A21,4) -> 0012 | C21: Renault Scope 2 MID Navi EUR DAB (FM) eCore | D21: 068E (Quad) | E21: imx | F21: RFS_GEN3_5 | G21: rivie_nav_full | H21: No_Chenc | I21: Bosch_Navigation | J21: Renault | K21: NAV-Full | L21: Renault_HMI_Scope_2.1 | M21: PARTITION_SCHEMA64__ST2X_NavRenault | N21: NO_EMMC | O21: EUR_SDB | P21: =IF(AND(OR(INDIRECT("K" & ROW())="NAV-Premium",INDIRECT("K" & ROW())="DA-Premium"),INDIRECT("M" & ROW())="PARTITION_SCHEMA128__NavPiviJpn", INDIRECT("O" & ROW())="JPN_SDB"),'SDB vs GN'!$B$41, IF(INDIRECT("H" & ROW())="Chenc",'SDB vs GN'!$B$40, VLOOKUP(INDIRECT("O" & ROW()),'SDB vs GN'!$A$16:$B$38,2,FALSE))) -> 731_EUR | Q21: V850_Scope_2 | R21: AARS_IVI_S2_AC_DAB | S21: Arkamys_Classic | T21: SXM_not_updatable | U21: eCore | V21: EUR_LP_ST2.1_R_MID | W21: Teseo_2_updatable | X21: FPGA_and_CPLD_not_updatable | Y21: NO_CPLD_PEXT | Z21: NO_ETH_SWITCH | AB21: 370 | AC21: 7.510.750.806-01 (' ') | AD21: use | AH21: [06.06.16] 0x68E = Teseo 2 (checked OK).
A22: 19 | B22: =DEC2HEX(A22,4) -> 0013 | C22: Nissan Scope 2 DA-MID RUS (AM/FM) | D22: 068C (Single) | E22: imx | F22: RFS_GEN3_3 | G22: rnaivi_da | H22: No_Chenc | I22: No_Navigation | J22: Nissan | K22: DA-Mid | L22: Nissan_HMI_Scope_2.0 | M22: PARTITION_SCHEMA8__DASdb | N22: NO_EMMC | O22: DA2_SDB | P22: =IF(AND(OR(INDIRECT("K" & ROW())="NAV-Premium",INDIRECT("K" & ROW())="DA-Premium"),INDIRECT("M" & ROW())="PARTITION_SCHEMA128__NavPiviJpn", INDIRECT("O" & ROW())="JPN_SDB"),'SDB vs GN'!$B$41, IF(INDIRECT("H" & ROW())="Chenc",'SDB vs GN'!$B$40, VLOOKUP(INDIRECT("O" & ROW()),'SDB vs GN'!$A$16:$B$38,2,FALSE))) -> 735_LA_831_AUSKRJPN | Q22: V850_Scope_2 | R22: AARS_IVI_S2_AC_FM | S22: Arkamys_Classic | T22: SXM_not_updatable | U22: No_eCore | V22: No_Map | W22: GNSS_not_updatable | X22: FPGA_and_CPLD_not_updatable | Y22: NO_CPLD_PEXT | Z22: NO_ETH_SWITCH | AB22: 343 | AC22: 7.500.750.802-01 (' ') | AD22: use | AH22: [06.06.16] 0x68C = Teseo 2 (checked OK). BUT no Navi therefore GNSS_not_updatable.
A23: 20 | B23: =DEC2HEX(A23,4) -> 0014 | C23: A-Sample: Nissan Scope 2 DA-MID NAR (FM) | D23: 0688 (Single) | E23: imx | F23: RFS_GEN3_3 | G23: rnaivi_da | H23: No_Chenc | I23: No_Navigation | J23: Nissan | K23: DA-Mid | L23: Nissan_HMI_Scope_2.0 | M23: PARTITION_SCHEMA32__NavSmallSdb | N23: NO_EMMC | O23: NAM_SDB | P23: =IF(AND(OR(INDIRECT("K" & ROW())="NAV-Premium",INDIRECT("K" & ROW())="DA-Premium"),INDIRECT("M" & ROW())="PARTITION_SCHEMA128__NavPiviJpn", INDIRECT("O" & ROW())="JPN_SDB"),'SDB vs GN'!$B$41, IF(INDIRECT("H" & ROW())="Chenc",'SDB vs GN'!$B$40, VLOOKUP(INDIRECT("O" & ROW()),'SDB vs GN'!$A$16:$B$38,2,FALSE))) -> 727_NAM | Q23: V850_Scope_2 | R23: AARS_IVI_S2_AC_FM | S23: Arkamys_Classic | T23: SXM_updatable | U23: No_eCore | V23: No_Map | W23: GNSS_not_updatable | X23: FPGA_and_CPLD_not_updatable | Y23: NO_CPLD_PEXT | Z23: NO_ETH_SWITCH | AB23: 390, 391, 392, 393 | AC23: 7.500.750.800-01 (' ') | AD23: use | AH23: 687 und 688 haben die selbe Teilenummer in der Variantenmatrix. Problem! Lösung: - Umbau auf 32 GB, d.h. auf 688 migrieren - Crashen erwartet Partition scheme was weired, but accepted as OK.
A24: 21 | B24: =DEC2HEX(A24,4) -> 0015 | C24: B-Sample: Nissan Scope 2 Entry Navi EUR (DAB) | D24: 068A (Single) | E24: imx | F24: RFS_GEN3_2 | G24: rnaivi_nav | H24: No_Chenc | I24: Bosch_Navigation | J24: Nissan | K24: NAV-Entry | L24: Nissan_HMI_Scope_2.0 | M24: PARTITION_SCHEMA32__NavLargeSdb | N24: NO_EMMC | O24: EUR_SDB | P24: =IF(AND(OR(INDIRECT("K" & ROW())="NAV-Premium",INDIRECT("K" & ROW())="DA-Premium"),INDIRECT("M" & ROW())="PARTITION_SCHEMA128__NavPiviJpn", INDIRECT("O" & ROW())="JPN_SDB"),'SDB vs GN'!$B$41, IF(INDIRECT("H" & ROW())="Chenc",'SDB vs GN'!$B$40, VLOOKUP(INDIRECT("O" & ROW()),'SDB vs GN'!$A$16:$B$38,2,FALSE))) -> 731_EUR | Q24: V850_Scope_2 | R24: AARS_IVI_S2_AC_DAB | S24: Arkamys_Classic | T24: SXM_not_updatable | U24: No_eCore | V24: EUR_ST2.0_N_ENTRY | W24: Teseo_2_updatable | X24: FPGA_and_CPLD_not_updatable | Y24: NO_CPLD_PEXT | Z24: NO_ETH_SWITCH | AB24: 368 369 | AC24: 7.510.750.826-01, 7.510.750.839-01 | AD24: use | AH24: [06.06.16] 0x68A = Teseo 2 (checked OK)
A25: 22 | B25: =DEC2HEX(A25,4) -> 0016 | C25: A-Sample: Renault Scope 2.1 Entry Navi EUR (DAB) | D25: 0691 (DL) | E25: imx | F25: RFS_GEN3_4 | G25: rivie_nav | H25: No_Chenc | I25: Bosch_Navigation | J25: Renault | K25: NAV-Entry | L25: Renault_HMI_Scope_2.1 | M25: PARTITION_SCHEMA16__ST2X_NavRenault | N25: NO_EMMC | O25: EUL_SDB | P25: =IF(AND(OR(INDIRECT("K" & ROW())="NAV-Premium",INDIRECT("K" & ROW())="DA-Premium"),INDIRECT("M" & ROW())="PARTITION_SCHEMA128__NavPiviJpn", INDIRECT("O" & ROW())="JPN_SDB"),'SDB vs GN'!$B$41, IF(INDIRECT("H" & ROW())="Chenc",'SDB vs GN'!$B$40, VLOOKUP(INDIRECT("O" & ROW()),'SDB vs GN'!$A$16:$B$38,2,FALSE))) -> 731_EUR | Q25: V850_Scope_2 | R25: AARS_IVI_S2_AC_DAB | S25: Arkamys_Classic | T25: SXM_not_updatable | U25: No_eCore | V25: EUR_LP_ST2.1_R_ENTRY | W25: Teseo_3_updatable | X25: FPGA_and_CPLD_not_updatable | Y25: NO_CPLD_PEXT | Z25: NO_ETH_SWITCH | AB25: 381 | AC25: 7.510.750.807-01 (' ') | AD25: block | AH25: [06.06.16] Inconsistencies for this variant. According to variant table Board-ID changed from 0x68A (Teseo 2, SingleCore) to 0x691 (Teseo 3, DualLite). Changed to 0x691 (Teseo 3, DualLite) for partnumber 7.510.750.807-01( ' ' ) based on VariantMatrix
A26: 23 | B26: =DEC2HEX(A26,4) -> 0017 | C26: A-Sample: Renault Scope 2.1 Entry Navi EUR (DAB) | D26: 068D (Single) | E26: imx | F26: RFS_GEN3_4 | G26: rivie_nav | H26: No_Chenc | I26: Bosch_Navigation | J26: Renault | K26: NAV-Entry | L26: Renault_HMI_Scope_2.1 | M26: PARTITION_SCHEMA16__ST2X_NavRenault | N26: NO_EMMC | O26: EUL_SDB | P26: =IF(AND(OR(INDIRECT("K" & ROW())="NAV-Premium",INDIRECT("K" & ROW())="DA-Premium"),INDIRECT("M" & ROW())="PARTITION_SCHEMA128__NavPiviJpn", INDIRECT("O" & ROW())="JPN_SDB"),'SDB vs GN'!$B$41, IF(INDIRECT("H" & ROW())="Chenc",'SDB vs GN'!$B$40, VLOOKUP(INDIRECT("O" & ROW()),'SDB vs GN'!$A$16:$B$38,2,FALSE))) -> 731_EUR | Q26: V850_Scope_2 | R26: AARS_IVI_S2_AC_DAB | S26: Arkamys_Classic | T26: SXM_not_updatable | U26: No_eCore | V26: EUR_LP_ST2.1_R_ENTRY | W26: Teseo_2_updatable | X26: FPGA_and_CPLD_not_updatable | Y26: NO_CPLD_PEXT | Z26: NO_ETH_SWITCH | AB26: 372 | AC26: 7.510.750.829-01 (' ') | AD26: block | AH26: Variantentabelle hatte 16 GB als CRQ und 32GB als Ist-Stand gelistet. Reduziert von 32 GB auf 16 GB. [06.06.16] 0x68D = Teseo 2 (checked OK).
A27: 24 | B27: =DEC2HEX(A27,4) -> 0018 | C27: Nissan Scope 2 NAV-Mid JPN(JPN) (DARC) | D27: 068B (Quad) | E27: imx | F27: RFS_GEN3_2J | G27: rnaivi_nav_jpn | H27: No_Chenc | I27: Japan_Navigation | J27: Nissan | K27: NAV-Mid | L27: Nissan_HMI_Scope_2.0 | M27: PARTITION_SCHEMA32__NavSmallSdb | N27: NO_EMMC | O27: JPN_SDB | P27: =IF(AND(OR(INDIRECT("K" & ROW())="NAV-Premium",INDIRECT("K" & ROW())="DA-Premium"),INDIRECT("M" & ROW())="PARTITION_SCHEMA128__NavPiviJpn", INDIRECT("O" & ROW())="JPN_SDB"),'SDB vs GN'!$B$41, IF(INDIRECT("H" & ROW())="Chenc",'SDB vs GN'!$B$40, VLOOKUP(INDIRECT("O" & ROW()),'SDB vs GN'!$A$16:$B$38,2,FALSE))) -> 742_JPN_831_AUSKRJPN | Q27: V850_Scope_2 | R27: AARS_IVI_S2_AC_DARC | S27: Arkamys_Classic | T27: SXM_not_updatable | U27: No_eCore | V27: Japan (ST2.0_N_MID) | W27: Teseo_2_updatable | X27: FPGA_updatable | Y27: NO_CPLD_PEXT | Z27: NO_ETH_SWITCH | AB27: 367 | AC27: 7.510.750.837-01 | AD27: block | AH27: Partition scheme was weared, but accepted as OK.[06.06.16] 0x68B = Teseo 2 (checked OK)
A28: 25 | B28: =DEC2HEX(A28,4) -> 0019 | C28: Renault Scope 2 MID Navi NAR (FM) eCore | D28: 068E (Quad) | E28: imx | F28: RFS_GEN3_5 | G28: rivie_nav_full | H28: No_Chenc | I28: Bosch_Navigation | J28: Renault | K28: NAV-Full | L28: Renault_HMI_Scope_2.1 | M28: PARTITION_SCHEMA64__ST2X_NavRenault | N28: NO_EMMC | O28: NAM_SDB | P28: =IF(AND(OR(INDIRECT("K" & ROW())="NAV-Premium",INDIRECT("K" & ROW())="DA-Premium"),INDIRECT("M" & ROW())="PARTITION_SCHEMA128__NavPiviJpn", INDIRECT("O" & ROW())="JPN_SDB"),'SDB vs GN'!$B$41, IF(INDIRECT("H" & ROW())="Chenc",'SDB vs GN'!$B$40, VLOOKUP(INDIRECT("O" & ROW()),'SDB vs GN'!$A$16:$B$38,2,FALSE))) -> 727_NAM | Q28: V850_Scope_2 | R28: AARS_IVI_S2_AC_HD | S28: Arkamys_Classic | T28: SXM_updatable | U28: eCore | V28: NAM_LP_ST2.1_R_MID | W28: Teseo_2_updatable | X28: FPGA_and_CPLD_not_updatable | Y28: NO_CPLD_PEXT | Z28: NO_ETH_SWITCH | AB28: 371 | AC28: 7.510.750.834-01 (' ') | AD28: use | AH28: [06.06.16] 0x68E = Teseo 2 (checked OK). [wzr2hi, 22.08.16] This is the only Renault-Variant with SXM
A29: 26 | B29: =DEC2HEX(A29,4) -> 001A | C29: Nissan Scope 2 DA-MID NAR (AM/FM) | D29: 068C (Single) | E29: imx | F29: RFS_GEN3_3 | G29: rnaivi_da | H29: No_Chenc | I29: No_Navigation | J29: Nissan | K29: DA-Mid | L29: Nissan_HMI_Scope_2.0 | M29: PARTITION_SCHEMA8__DASdb | N29: NO_EMMC | O29: NAM_SDB | P29: =IF(AND(OR(INDIRECT("K" & ROW())="NAV-Premium",INDIRECT("K" & ROW())="DA-Premium"),INDIRECT("M" & ROW())="PARTITION_SCHEMA128__NavPiviJpn", INDIRECT("O" & ROW())="JPN_SDB"),'SDB vs GN'!$B$41, IF(INDIRECT("H" & ROW())="Chenc",'SDB vs GN'!$B$40, VLOOKUP(INDIRECT("O" & ROW()),'SDB vs GN'!$A$16:$B$38,2,FALSE))) -> 727_NAM | Q29: V850_Scope_2 | R29: AARS_IVI_S2_AC_HD | S29: Arkamys_Classic | T29: SXM_updatable | U29: No_eCore | V29: No_Map | W29: GNSS_not_updatable | X29: FPGA_and_CPLD_not_updatable | Y29: NO_CPLD_PEXT | Z29: NO_ETH_SWITCH | AB29: 453 | AC29: 7.500.750.812-01 (' ') | AD29: use | AH29: Variantentabelle wurde aktualisiert und SWUP-Tabelle nachgezogen. [06.06.16] 0x68C = Teseo 2 (checked OK). BUT no Navi therefore GNSS_not_updatable.
A30: 27 | B30: =DEC2HEX(A30,4) -> 001B | C30: Renault Scope 2 MID Navi EUR DAB eCore | D30: 0696 (Quad) | E30: imx | F30: RFS_GEN3_5 | G30: rivie_nav_full | H30: No_Chenc | I30: Bosch_Navigation | J30: Renault | K30: NAV-Full | L30: Renault_HMI_Scope_2.1 | M30: PARTITION_SCHEMA64__ST2X_NavRenault | N30: NO_EMMC | O30: EUR_SDB | P30: =IF(AND(OR(INDIRECT("K" & ROW())="NAV-Premium",INDIRECT("K" & ROW())="DA-Premium"),INDIRECT("M" & ROW())="PARTITION_SCHEMA128__NavPiviJpn", INDIRECT("O" & ROW())="JPN_SDB"),'SDB vs GN'!$B$41, IF(INDIRECT("H" & ROW())="Chenc",'SDB vs GN'!$B$40, VLOOKUP(INDIRECT("O" & ROW()),'SDB vs GN'!$A$16:$B$38,2,FALSE))) -> 731_EUR | Q30: V850_Scope_2 | R30: AARS_IVI_S2_AC_DAB | S30: Arkamys_Classic | T30: SXM_not_updatable | U30: eCore | V30: EUR_LP_ST2.1_R_MID | W30: Teseo_3_updatable | X30: FPGA_and_CPLD_not_updatable | Y30: NO_CPLD_PEXT | Z30: NO_ETH_SWITCH | AC30: 7.510.750.869-01[discarded] | AD30: ignore | AH30: [06.06.16] 0x696 = Teseo 3 (checked OK). Please use FCID 44. This is a double.
A31: 28 | B31: =DEC2HEX(A31,4) -> 001C | C31: Renault Scope 2 Entry Navi EUR DAB eCore | D31: 068F (DL) | E31: imx | F31: RFS_GEN3_4 | G31: rivie_nav | H31: No_Chenc | I31: Bosch_Navigation | J31: Renault | K31: NAV-Entry | L31: Renault_HMI_Scope_2.1 | M31: PARTITION_SCHEMA16__ST2X_NavRenault | N31: NO_EMMC | O31: EUL_SDB | P31: =IF(AND(OR(INDIRECT("K" & ROW())="NAV-Premium",INDIRECT("K" & ROW())="DA-Premium"),INDIRECT("M" & ROW())="PARTITION_SCHEMA128__NavPiviJpn", INDIRECT("O" & ROW())="JPN_SDB"),'SDB vs GN'!$B$41, IF(INDIRECT("H" & ROW())="Chenc",'SDB vs GN'!$B$40, VLOOKUP(INDIRECT("O" & ROW()),'SDB vs GN'!$A$16:$B$38,2,FALSE))) -> 731_EUR | Q31: V850_Scope_2 | R31: AARS_IVI_S2_AC_DAB | S31: Arkamys_Classic | T31: SXM_not_updatable | U31: No_eCore | V31: EUR_LP_ST2.1_R_ENTRY | W31: Teseo_3_updatable | X31: FPGA_and_CPLD_not_updatable | Y31: NO_CPLD_PEXT | Z31: NO_ETH_SWITCH | AB31: 375 378 379 | AC31: 7.510.750.808-01( 'HW 001' ), 7.510.750.840-01( 'HW 001' ), 7.510.750.841-01( 'HW 001' ) | AD31: block | AH31: [06.06.16] 0x68D = Teseo 3 (checked OK).
A32: 29 | B32: =DEC2HEX(A32,4) -> 001D | C32: Renault Scope 2.1 Entry Navi EUR DAB ex:eCore | D32: 0691 (DL) | E32: imx | F32: RFS_GEN3_4 | G32: rivie_nav | H32: No_Chenc | I32: Bosch_Navigation | J32: Renault | K32: NAV-Entry | L32: Renault_HMI_Scope_2.1 | M32: PARTITION_SCHEMA16__ST2X_NavRenault | N32: NO_EMMC | O32: EUL_SDB | P32: =IF(AND(OR(INDIRECT("K" & ROW())="NAV-Premium",INDIRECT("K" & ROW())="DA-Premium"),INDIRECT("M" & ROW())="PARTITION_SCHEMA128__NavPiviJpn", INDIRECT("O" & ROW())="JPN_SDB"),'SDB vs GN'!$B$41, IF(INDIRECT("H" & ROW())="Chenc",'SDB vs GN'!$B$40, VLOOKUP(INDIRECT("O" & ROW()),'SDB vs GN'!$A$16:$B$38,2,FALSE))) -> 731_EUR | Q32: V850_Scope_2 | R32: AARS_IVI_S2_AC_DAB | S32: Arkamys_Classic | T32: SXM_not_updatable | U32: No_eCore | V32: EUR_LP_ST2.1_R_ENTRY | W32: Teseo_3_updatable | X32: FPGA_and_CPLD_not_updatable | Y32: NO_CPLD_PEXT | Z32: NO_ETH_SWITCH | AB32: 421 | AC32: 7.510.750.807-01('HW 001')[discarded], 7.510.750.867-01('HW 001') | AD32: block | AH32: [06.06.16] 0x691 = Teseo 3 (checked OK). 7.510.750.807-01('HW 001') deleted because now identical to 22. [01.09.2017] Corrected obsolete eCore setting. Results in the following identical FCIDs:0016-001D
A33: 30 | B33: =DEC2HEX(A33,4) -> 001E | C33: Nissan Scope 2 MID Navi EUR (DAB) | D33: 0691 (DL) | E33: imx | F33: RFS_GEN3_2 | G33: rnaivi_nav | H33: No_Chenc | I33: Bosch_Navigation | J33: Nissan | K33: NAV-Mid | L33: Nissan_HMI_Scope_2.0 | M33: PARTITION_SCHEMA32__NavLargeSdb | N33: NO_EMMC | O33: EUR_SDB | P33: =IF(AND(OR(INDIRECT("K" & ROW())="NAV-Premium",INDIRECT("K" & ROW())="DA-Premium"),INDIRECT("M" & ROW())="PARTITION_SCHEMA128__NavPiviJpn", INDIRECT("O" & ROW())="JPN_SDB"),'SDB vs GN'!$B$41, IF(INDIRECT("H" & ROW())="Chenc",'SDB vs GN'!$B$40, VLOOKUP(INDIRECT("O" & ROW()),'SDB vs GN'!$A$16:$B$38,2,FALSE))) -> 731_EUR | Q33: V850_Scope_2 | R33: AARS_IVI_S2_AC_DAB | S33: Arkamys_Classic | T33: SXM_not_updatable | U33: No_eCore | V33: EUR_ST2.0_N_MID | W33: Teseo_3_updatable | X33: FPGA_and_CPLD_not_updatable | Y33: NO_CPLD_PEXT | Z33: NO_ETH_SWITCH | AB33: 422 423 463 | AC33: 7.510.750.843-01('HW 001'), 7.510.750.849-01('HW 001')[discarded], 7.510.750.845-01('HW 001')[discarded], 7.510.750.815-01('HW 001') | AD33: use | AH33: [06.06.16] 0x691 = Teseo 3 (checked OK). [wzr2hi, 23.08.2016] 7.510.750.845-01 replaced by FCID 0x0040 below. [wzr2hi, 31.01.2017] 7.510.750.849-01 replaced by FCID 0x005E below.
A34: 31 | B34: =DEC2HEX(A34,4) -> 001F | C34: Nissan Scope 2 MID Navi NAM(US) (HD) | D34: 0691 (DL) | E34: imx | F34: RFS_GEN3_2 | G34: rnaivi_nav | H34: No_Chenc | I34: Bosch_Navigation | J34: Nissan | K34: NAV-Mid | L34: Nissan_HMI_Scope_2.0 | M34: PARTITION_SCHEMA32__NavSmallSdb | N34: NO_EMMC | O34: NAM_SDB | P34: =IF(AND(OR(INDIRECT("K" & ROW())="NAV-Premium",INDIRECT("K" & ROW())="DA-Premium"),INDIRECT("M" & ROW())="PARTITION_SCHEMA128__NavPiviJpn", INDIRECT("O" & ROW())="JPN_SDB"),'SDB vs GN'!$B$41, IF(INDIRECT("H" & ROW())="Chenc",'SDB vs GN'!$B$40, VLOOKUP(INDIRECT("O" & ROW()),'SDB vs GN'!$A$16:$B$38,2,FALSE))) -> 727_NAM | Q34: V850_Scope_2 | R34: AARS_IVI_S2_AC_HD | S34: Arkamys_Classic | T34: SXM_updatable | U34: No_eCore | V34: NAM_ST2.0_N_MID | W34: Teseo_3_updatable | X34: FPGA_and_CPLD_not_updatable | Y34: NO_CPLD_PEXT | Z34: NO_ETH_SWITCH | AB34: 424 425 460 458 457 | AC34: 7.510.750.842-01('HW 001'), 7.510.750.848-01('HW 001'), 7.510.750.844-01('HW 001'), 7.510.750.850-01('HW 001')[discarded], 7.510.750.861-01('HW 001')[discarded], 7.510.750.833-01('HW 001') | AD34: use | AH34: [06.06.16] 0x691 = Teseo 3 (checked OK). [wzr2hi, 23.08.2016] 7.510.750.850-01 replaced by FCID 65 below. [wzr2hi, 19.05.2017] 7.510.750.861-01 replaced by FCID 0x0xxx below (due to collision after FPGA consolidation).
A35: 32 | B35: =DEC2HEX(A35,4) -> 0020 | C35: Nissan Scope 2 MID Navi MEX (HD) | D35: 0691 (DL) | E35: imx | F35: RFS_GEN3_2 | G35: rnaivi_nav | H35: No_Chenc | I35: Bosch_Navigation | J35: Nissan | K35: NAV-Mid | L35: Nissan_HMI_Scope_2.0 | M35: PARTITION_SCHEMA32__NavSmallSdb | N35: NO_EMMC | O35: NAM_SDB | P35: =IF(AND(OR(INDIRECT("K" & ROW())="NAV-Premium",INDIRECT("K" & ROW())="DA-Premium"),INDIRECT("M" & ROW())="PARTITION_SCHEMA128__NavPiviJpn", INDIRECT("O" & ROW())="JPN_SDB"),'SDB vs GN'!$B$41, IF(INDIRECT("H" & ROW())="Chenc",'SDB vs GN'!$B$40, VLOOKUP(INDIRECT("O" & ROW()),'SDB vs GN'!$A$16:$B$38,2,FALSE))) -> 727_NAM | Q35: V850_Scope_2 | R35: AARS_IVI_S2_AC_HD | S35: Arkamys_Classic | T35: SXM_not_updatable | U35: No_eCore | V35: NAMEX_ST2.0_N_MID | W35: Teseo_3_updatable | X35: FPGA_and_CPLD_not_updatable | Y35: NO_CPLD_PEXT | Z35: NO_ETH_SWITCH | AB35: 456 | AC35: 7.510.750.866-01('HW 001') | AD35: use | AH35: [06.06.16] 0x691 = Teseo 3 (checked OK).
A36: 33 | B36: =DEC2HEX(A36,4) -> 0021 | C36: Nissan Scope 2 MID Navi PRC (AM/FM) | D36: 0691 (DL) | E36: imx | F36: RFS_GEN3_2 | G36: rnaivi_nav | H36: Chenc | I36: Bosch_Navigation | J36: Nissan | K36: NAV-Mid | L36: Nissan_HMI_Scope_2.0 | M36: PARTITION_SCHEMA32__NavSmallSdb | N36: NO_EMMC | O36: PRC_SDB | P36: =IF(AND(OR(INDIRECT("K" & ROW())="NAV-Premium",INDIRECT("K" & ROW())="DA-Premium"),INDIRECT("M" & ROW())="PARTITION_SCHEMA128__NavPiviJpn", INDIRECT("O" & ROW())="JPN_SDB"),'SDB vs GN'!$B$41, IF(INDIRECT("H" & ROW())="Chenc",'SDB vs GN'!$B$40, VLOOKUP(INDIRECT("O" & ROW()),'SDB vs GN'!$A$16:$B$38,2,FALSE))) -> 734_CN_831_AUSKRJPN_CHENC | Q36: V850_Scope_2 | R36: AARS_IVI_S2_AC_FM | S36: Arkamys_Classic | T36: SXM_not_updatable | U36: No_eCore | V36: PRC_ST2.0_N_MID | W36: Teseo_3_updatable | X36: FPGA_and_CPLD_not_updatable | Y36: NO_CPLD_PEXT | Z36: NO_ETH_SWITCH | AB36: 426 | AC36: 7.510.750.862-01('HW 001')[discarded] | AD36: ignore | AH36: [06.06.16] 0x691 = Teseo 3 (checked OK). [wzr2hi, 31.01.2017] 7.510.750.862-01 replaced by FCID 005F below. [wzr2hi, 26.04.2017] Changed GN_734 to 734_CN_831_AUSKRJPN according to Stefan Weber.
A37: 34 | B37: =DEC2HEX(A37,4) -> 0022 | C37: Nissan Scope 2 MID Navi ASEAN (AM/FM) | D37: 0691 (DL) | E37: imx | F37: RFS_GEN3_2 | G37: rnaivi_nav | H37: No_Chenc | I37: Bosch_Navigation | J37: Nissan | K37: NAV-Mid | L37: Nissan_HMI_Scope_2.0 | M37: PARTITION_SCHEMA32__NavSmallSdb | N37: NO_EMMC | O37: PRC_SDB | P37: =IF(AND(OR(INDIRECT("K" & ROW())="NAV-Premium",INDIRECT("K" & ROW())="DA-Premium"),INDIRECT("M" & ROW())="PARTITION_SCHEMA128__NavPiviJpn", INDIRECT("O" & ROW())="JPN_SDB"),'SDB vs GN'!$B$41, IF(INDIRECT("H" & ROW())="Chenc",'SDB vs GN'!$B$40, VLOOKUP(INDIRECT("O" & ROW()),'SDB vs GN'!$A$16:$B$38,2,FALSE))) -> 734_CN_831_AUSKRJPN | Q37: V850_Scope_2 | R37: AARS_IVI_S2_AC_FM | S37: Arkamys_Classic | T37: SXM_not_updatable | U37: No_eCore | V37: APAC_ST2.0_N_MID | W37: Teseo_3_updatable | X37: FPGA_updatable | Y37: NO_CPLD_PEXT | Z37: NO_ETH_SWITCH | AB37: 455 | AC37: 7.510.750.864-01('HW 001')[discarded] | AD37: ignore | AH37: [06.06.16] 0x691 = Teseo 3 (checked OK). [wzr2hi, 28.10.16] 7.510.750.864-01('HW 001') - 0691 (DL) removed due to different Board-ID - replaced by FCID 80 below
A38: 35 | B38: =DEC2HEX(A38,4) -> 0023 | C38: Nissan Scope 2 NAV-Mid JPN(JPN) (DARC) | D38: 0692 (Quad) | E38: imx | F38: RFS_GEN3_2J | G38: rnaivi_nav_jpn | H38: No_Chenc | I38: Japan_Navigation | J38: Nissan | K38: NAV-Mid | L38: Nissan_HMI_Scope_2.0 | M38: PARTITION_SCHEMA64__NavRenault | N38: NO_EMMC | O38: JPN_SDB | P38: =IF(AND(OR(INDIRECT("K" & ROW())="NAV-Premium",INDIRECT("K" & ROW())="DA-Premium"),INDIRECT("M" & ROW())="PARTITION_SCHEMA128__NavPiviJpn", INDIRECT("O" & ROW())="JPN_SDB"),'SDB vs GN'!$B$41, IF(INDIRECT("H" & ROW())="Chenc",'SDB vs GN'!$B$40, VLOOKUP(INDIRECT("O" & ROW()),'SDB vs GN'!$A$16:$B$38,2,FALSE))) -> 742_JPN_831_AUSKRJPN | Q38: V850_Scope_2 | R38: AARS_IVI_S2_AC_DARC | S38: Arkamys_Classic | T38: SXM_not_updatable | U38: No_eCore | V38: Japan (ST2.0_N_MID) | W38: Teseo_3_updatable | X38: FPGA_updatable | Y38: NO_CPLD_PEXT | Z38: NO_ETH_SWITCH | AB38: 366 440 | AC38: 7.510.750.813-01('HW 001'), 7.510.750.863-01('HW 001')[discarded] | AD38: block_le20 | AF38: would repart but blocked for ST2.0 anyway | AH38: [06.06.16] 0x692 = Teseo 3 (checked OK). [wzr2hi, 28.10.16] 7.510.750.863-01('HW 001') - 0692 (Quad) removed due to different Board-ID - replaced by FCID 81 below
A39: 36 | B39: =DEC2HEX(A39,4) -> 0024 | C39: Nissan Scope 2 DA-MID NAR (AM/FM) | D39: 0693 (Single) | E39: imx | F39: RFS_GEN3_3 | G39: rnaivi_da | H39: No_Chenc | I39: No_Navigation | J39: Nissan | K39: DA-Mid | L39: Nissan_HMI_Scope_2.0 | M39: PARTITION_SCHEMA8__DASdb | N39: NO_EMMC | O39: NAM_SDB | P39: =IF(AND(OR(INDIRECT("K" & ROW())="NAV-Premium",INDIRECT("K" & ROW())="DA-Premium"),INDIRECT("M" & ROW())="PARTITION_SCHEMA128__NavPiviJpn", INDIRECT("O" & ROW())="JPN_SDB"),'SDB vs GN'!$B$41, IF(INDIRECT("H" & ROW())="Chenc",'SDB vs GN'!$B$40, VLOOKUP(INDIRECT("O" & ROW()),'SDB vs GN'!$A$16:$B$38,2,FALSE))) -> 727_NAM | Q39: V850_Scope_2 | R39: AARS_IVI_S2_AC_FM | S39: Arkamys_Classic | T39: SXM_updatable | U39: No_eCore | V39: No_Map | W39: Teseo_3_updatable | X39: FPGA_and_CPLD_not_updatable | Y39: NO_CPLD_PEXT | Z39: NO_ETH_SWITCH | AB39: 427 | AC39: 7.500.750.806-01('HW 001')[discarded], 7.500.750.807-01('HW 001')[discarded] | AD39: ignore | AH39: [06.06.16] 0x693 = Teseo 3 (checked OK). [wzr2hi, 23.08.2016] 7.500.750.807-01 replaced by FCID 0x003D below. [wzr2hi, 31.01.2017] 7.500.750.806-01 replaced by FCID 0x0068 below
A40: 37 | B40: =DEC2HEX(A40,4) -> 0025 | C40: Nissan Scope 2 DA RUS (AM/FM) | D40: 0693 (Single) | E40: imx | F40: RFS_GEN3_3 | G40: rnaivi_da | H40: No_Chenc | I40: No_Navigation | J40: Nissan | K40: DA-Mid | L40: Nissan_HMI_Scope_2.0 | M40: PARTITION_SCHEMA8__DASdb | N40: NO_EMMC | O40: DA2_SDB | P40: =IF(AND(OR(INDIRECT("K" & ROW())="NAV-Premium",INDIRECT("K" & ROW())="DA-Premium"),INDIRECT("M" & ROW())="PARTITION_SCHEMA128__NavPiviJpn", INDIRECT("O" & ROW())="JPN_SDB"),'SDB vs GN'!$B$41, IF(INDIRECT("H" & ROW())="Chenc",'SDB vs GN'!$B$40, VLOOKUP(INDIRECT("O" & ROW()),'SDB vs GN'!$A$16:$B$38,2,FALSE))) -> 735_LA_831_AUSKRJPN | Q40: V850_Scope_2 | R40: AARS_IVI_S2_AC_FM | S40: Arkamys_Classic | T40: SXM_not_updatable | U40: No_eCore | V40: No_Map | W40: Teseo_3_updatable | X40: FPGA_and_CPLD_not_updatable | Y40: NO_CPLD_PEXT | Z40: NO_ETH_SWITCH | AC40: 7.500.750.811-01('HW 001')[discarded] | AD40: ignore | AH40: [06.06.16] 0x693 = Teseo 3 (checked OK). [wzr2hi, 23.08.2016] 7.500.750.811-01 replaced by FCID 0x003E below. [wzr2hi, 23.08.2016] FCID 0037/0x0025 obsolete and blocked.
...

Sheet Variability definition
A1: Board-ID | B1: RAM implemented [GB] | C1: Board ID/DTB | D1: RFS | E1: China Encoder | F1: Navigation | G1: Customer (fixed by RFS) | H1: Type (fixed by RFS) | I1: HMI (fixed by RFS) | J1: Partitioning scheme (old, deprecated) | K1: Partitioning scheme (till 23.10.2017, deprecated) | L1: Partitioning scheme (new) | M1: SDB Data | N1: V850 (depends on Board-ID) | O1: ADR_FW_Type | P1: Arkamys (Part of ADR) | Q1: Gracenote | R1: SXM | S1: eCore | T1: Map Data (only for production) | U1: GNSS | V1: FPGA/CPLD | W1: CPLD (CORE) | X1: GenCtrl
A2: 681 | B2: 2 | C2: CS Customer Sample | D2: RFS_GEN3_1 nivic (Scope1_Nissan) | E2: No_Chenc | F2: No_Navigation | G2: Nissan | H2: DA-Entry | I2: Nissan_HMI_Scope_1.0 | J2: 8 GB (EU) PARTITION_SCHEMA8_NissanScope1 | L2: 8GB (Scope1 EU) PARTITION_SCHEMA8_NissanScope1 | M2: No_SDB | N2: V850_Scope_1 | O2: AARS_IVI_S0_NA_DAB | P2: No_Arkamys | Q2: No_Gracenote | R2: SXM_not_updatable | S2: No_eCore | T2: see comment of column | U2: GNSS_not_updatable | V2: FPGA_and_CPLD_not_updatable | W2: NO_CPLD_PEXT | X2: use
A3: 682 | B3: 2 | C3: ES Engineering Sample | D3: RFS_GEN3_2 rnaivi_nav (A-IVI_Scope2.*_Nissan_Nav_MID/Entry) (ROW-Navi and JPN-Navi installed in parallel) (no China-Encoder installed) | E3: Chenc | F3: Bosch_Navigation | G3: Renault | H3: DA-Mid | I3: Nissan_HMI_Scope_2.0 | J3: 8 GB (Entry All Variants after ST2.0 NAR, EU….) PARTITION_SCHEMA8_DaEntry | K3: 8GB (all Renault Entry-DAs) PARTITION_SCHEMA8__DA | L3: 8GB (all Renault Entry-DAs (Affordable, Access, Core)) PARTITION_SCHEMA8__DARenaultObigo | M3: EUR_SDB (Europe, Turkey, South Africa, Australia, New Zealand) | N3: V850_Scope_2 (former V850_common) | O3: AARS_IVI_S0_NA_HD | P3: Arkamys_Classic | Q3: 731_EUR (EUR, RUS, GCC) | R3: SXM_not_updatable_fw | S3: eCore | U3: Teseo_2_updatable | V3: CPLD_updatable | W3: CPLD_PEXT_CLEO_A | X3: ignore
A4: 0683 (DL) | B4: 2 | C4: WS Working Sample | D4: RFS_GEN3_2C rnaivi_nav_chn (A-IVI_Scope2.*_Nissan_Nav_MID/Entry) (only ROW-Navi installed) (China-Encoder installed) | F4: Japan_Navigation | G4: Daimler | H4: DA-Premium | I4: Nissan_HMI_Scope_2.1 | J4: 8 GB (MID All Variants after ST2.0 NAR, EU….) PARTITION_SCHEMA8_DaMid | L4: 8GB (all Nissan Entry-DAs / all Alliance Mid-DAs) PARTITION_SCHEMA8__DASdb | M4: NAM_SDB (USA, Canada, Mexiko) | N4: V850_PIVI_C1 | O4: AARS_IVI_S1_NA_FM | P4: Arkamys_Auditorium | Q4: 727_NAM (US, CAN, MEX) | R4: SXM_updatable | U4: Teseo_3_updatable | V4: FPGA_updatable | W4: CPLD_PEXT_ADR_A | X4: block
A5: 0684 (Quad) | B5: 2 | D5: RFS_GEN3_2J rnaivi_nav_jpn (A-IVI_Scope2.*_Nissan_Nav_MID low res) (A-IVI_Scope3.*_Nissan_Nav_MID high res) (BOSCH, KOR and JPN-Navi installed) | F5: Korea_Navigation | G5: Mitsubishi | H5: NAV-Entry | I5: Renault_HMI_Scope_2.1 | J5: 16 GB (all Variants NAR, EU, .. Mid, Nissan Scope 0 Entry) PARTITION_SCHEMA16_NavEntryMidAllianceOther | L5: 16GB (all Variants with this eMMC size) PARTITION_SCHEMA16__Nav | M5: RUS_SDB (Russia) | O5: AARS_IVI_S2_AC_FM | Q5: 735_LA (LAC: Brasil, Argentinia, Chile ...) | U5: UBlox_updatable | V5: EXT_FPGA_updatable | W5: CPLD_PEXT_SBR_A | X5: block_le20
A6: 0685 (Single) | B6: 0.5 | D6: RFS_GEN3_3 rnaivi_da (A-IVI_Scope2.*_Nissan_DA_MID/Entry) | H6: NAV-Mid | I6: Nissan_HMI_Scope_3.1 | J6: 16 GB (Renault Variants NAR, EU, .. Entry) PARTITION_SCHEMA16_NavEntryRenaultEuNarChn | L6: 16GB (all Variants with this eMMC size) PARTITION_SCHEMA16__Nav | M6: GCC_SDB (Middle East, Mediterranian, Egypt, India) | O6: AARS_IVI_S2_AC_DAB | Q6: 734_CN (China) | V6: FPGA_and_CPLD_updatable | X6: block_le21
A7: 0686 (Single) | B7: 0.5 | D7: RFS_GEN3_4 rivie_nav (A-IVI_Scope2.1_Renault_Nav_Access/Core) (only ROW-Navi installed) (no managed apps installed) | H7: NAV-Premium | I7: Renault_HMI_Scope_3.0 | J7: 32 GB (NAR/MEX, CN, …. Entry/MID Nissan) PARTITION_SCHEMA32_NavEntryMidNissanNarChn | L7: 32GB (Nissan: all Entry-Nav and all Mid-Nav with 0 Gib < SDB < 1.3GiB Specification) PARTITION_SCHEMA32__NavSmallSdb | M7: PRC_SDB (China, Macao, Hong Kong) | O7: AARS_IVI_S2_AC_HD (NA+MEX) | Q7: 734_CN_831_AUSKRJPN (EUR/ASR/NZE/GOM for non-China)
A8: 0687 (Single) | B8: 0.5 | D8: RFS_GEN3_4C rivie_nav_chn (A-IVI_Scope2.1_Renault_Nav_MID/Entry) (only ROW-Navi installed) (China-Encoder installed) (no managed apps installed) | H8: DA-Access | I8: Daimler_HMI_Scope_3.0 | J8: 32 GB (EU, RUS, Others…. Entry/MID Nissan) PARTITION_SCHEMA32_NavEntryMidNissanEu | L8: 32GB (Nissan: all Entry-Nav and all Mid-Nav with 1.3GiB < SDB < 2.8GiB Specification) PARTITION_SCHEMA32__NavLargeSdb | M8: JPN_SDB (Japan) | O8: AARS_IVI_S2_AC_DARC (JPN) | Q8: 734_CN_831_AUSKRJPN_CHENC (EUR/ASR/NZE/GOM with China Encoder for China Mainland only)
A9: 0688 (Single) | B9: 1 | D9: RFS_GEN3_5 rivie_nav_full (A-IVI_Scope2.1_Renault_Nav_Full) (only ROW-Navi installed) (manged apps installed) | H9: DA-Affordable | I9: Nissan_HMI_P-IVI_2.1 | L9: 32GB (Renault: all Entry-Nav and all Mid-Nav with 0 Gib < SDB < 1.3GiB Specification) PARTITION_SCHEMA32__NavNissanNarObigo | M9: LAC_SDB (Latin America) | O9: AARS_IVI_S2_AC_DRM (IND) | Q9: 831_AUSKRJPN (JPN)
A10: 0689 (DL) | B10: 2 | D10: RFS_GEN3_5C rivie_nav_full_chn (A-IVI_Scope2.1_Renault_Nav_MID/Entry) (only ROW-Navi installed) (China-Encoder installed) (manged apps installed) | H10: DA-Core | I10: Nissan_HMI_P-IVI_3.1 | L10: 32GB (Renault: all Entry-Nav and all Mid-Nav with 1.3GiB < SDB < 2.8GiB Specification) PARTITION_SCHEMA32__NavNissanObigo | M10: GOM_SDB (Taiwan and Global other markets) | O10: AARS_IVI_S2_AC_FMSD
A11: 068A (Single) | B11: 2 | D11: RFS_GEN3_6 rivie_da (A-IVI_Scope2.1_Renault_DA_Access) | H11: Nav-Access | I11: Nissan_TCS_HMI_Scope_3.1 | L11: 32GB (all Renault DA-Full and Nissan DA-Premium with 3GiB RFS, [full Obigo] and SDB < 2.8GiB Specification) PARTITION_SCHEMA32__DA | M11: ASR_SDB (Africa/SAF/AUS/NZ) | O11: AARS_IVI_A2_P1_DAB
A12: 068B (Quad) | B12: 2 | D12: RFS_GEN3_7 rivie_da_core (A-IVI_Scope2.1_Renault_DA_Affordable/Core) | H12: Nav-Core | I12: Renault_HMI_Scope_1.1 | J12: 64 GB (all RenaultVariants, Nissan P-IVI) -> Nissan TBC PARTITION_SCHEMA64__NavRenault | L12: 64GB (all Variants with this eMMC size) PARTITION_SCHEMA64__NavRenault | O12: AARS_IVI_A2_P1_DARC
A13: 068C (Single) | B13: 1 | D13: RFS_GEN3_8 npivi_nav (P-IVI_Nissan_Nav*) (ROW-Navi and JPN-Navi installed in parallel) | H13: Nav-Full | I13: Mitsubishi_TCS_HMI_Scope_3.1 | L13: 128GB (all Variants with this eMMC size) PARTITION_SCHEMA128__NavPiviJpn | O13: AARS_IVI_A2_P1_FM
A14: 068D (Single) | B14: 2 | D14: RFS_GEN3_9 npivi_da (P-IVI_Nissan_DA*) | O14: AARS_IVI_A2_P1_HD
A15: 068E (Quad) | B15: 2 | D15: RFS_GEN3_10 rivie_nav (A-IVI_Scope3.0_Renault_Nav_Access/Core) (only ROW-Navi installed - TBD) (no managed apps installed) | O15: AARS_IVI2_SBR_AC_DAB
A16: 068F (DL) | B16: 2 | D16: RFS_GEN3_11 rivie_nav_full (A-IVI_Scope3.0_Renault_Nav_Full) (only ROW-Navi installed - TBD) (manged apps installed) | O16: AARS_IVI2_SBR_AC_DARC
A17: 0691 (DL) | B17: 2 | D17: RFS_GEN3_12 rivie_da (A-IVI_Scope3.0_Renault_DA_Access) | O17: AARS_IVI2_SBR_AC_FM
A18: 0692 (Quad) | B18: 2 | D18: RFS_GEN3_13 rivie_da_core (A-IVI_Scope3.0_Renault_DA_Affordable/Core) | O18: AARS_IVI2_SBR_AC_HD
A19: 0693 (Single) | B19: 1 | D19: RFS_GEN3_20 (Scope3.1_Nissan_reserved_DA)
A20: 0694 (DL) | B20: 2 | D20: RFS_GEN3_21 rnaivi_nav_high (Scope3.1_Nissan_reserved_NAV) (A-IVI_Scope3.1_Nissan_Nav_MID) (ROW-Navi and JPN-Navi installed in parallel) (no China-Encoder installed)
A21: 0695 (Single) | B21: 1 | D21: RFS_GEN3_21J rnaivi_nav_jpn (A-IVI_Scope3.*_Nissan_Nav_MID ??? res) (BOSCH, KOR and JPN-Navi installed)
A22: 0696 (Quad) | B22: 2 | D22: RFS_GEN3_22 divie_da_core (A-IVI_Scope3.0_Daimler_DA_Affordable/Core)
A23: 0697 (DL) | B23: 2
A24: 0698 (Quad) | B24: 2
A25: 0699 (DL) | B25: 1
A26: 069A (Quad) | B26: 4
A27: 069B (Single) | B27: 1 | D27: RFS_GEN4_8 npivi2_nav (P-IVI2_Nissan_Nav*)
A28: 069C (DL) | B28: 2 | D28: RFS_GEN4_9 npivi2_da (P-IVI2_Nissan_DA*)
A29: 069D (Quad) | B29: 2 | D29: RFS_GEN4_11 rivie2_nav_full (A-IVI2_Renault_Nav_Full)
A30: 069E (Single) | B30: 1 | D30: RFS_GEN4_20 rnaivi2_da (A-IVI2_Nissan_DA*)
A31: 069F (DL) | B31: 2 | D31: RFS_GEN4_21 rnaivi2_nav (A-IVI2_Nissan_Nav*)
A32: 06A1 (Quad) | B32: 2 | D32: RFS_GEN4_21H rnaivi2_nav_high (A-IVI2_Nissan_Nav_H3)
A33: 06A2 (DL) | B33: 0.5 | D33: RFS_GEN4_21J rnaivi2_nav_jpn (A-IVI2_Nissan_Nav_Jpn)
A34: 06A3 (QuadPlus) | B34: 4 | D34: RFS_GEN4_30 mmcivi2_da (A-IVI2_Mitsubishi_DA*) | H34: CRQ140 erfindet die Core Nav, ist aber noch nicht bestätigt:
A35: 06A4 (QuadPlus) | B35: 2 | D35: RFS_GEN4_31 mmcivi2_nav (A-IVI2_Mitsubishi_Nav*) | H35: kein DA@Renault hat SDB
A36: 06A5 (QuadPlus) | D36: RFS_GEN4_31H mmcivi2_nav_high (A-IVI2_Mitsubishi_Nav_H3) | H36: alle DA mit DualLite sollen Obigo (Lite) bekommen
A37: 06A6 (DL) | B37: 1 | D37: RFS_GEN4_31J mmcivi2_nav_jpn (A-IVI2_Mitsubishi_Nav_Jpn) | H37: alle Navis (ausser Access) sollen Obigo bekommen
A38: 06A7 (DL) | B38: 2 | H38: Mid-Nav is identicall to Full-Nav
A39: 06A8 (Quad) | B39: 2 | H39: Entry-Nav is either Access-Nav oder Core-Nav (Core-Nav mean: Full-Nav-Feature adapted for Entry-HW)
A40: 0701 (Quad) | B40: 2
...

Sheet Sticks
A2: Sticks | B2: SW_Variant_ID / FCID
A3: Stick 1 | B3: 1
A4: Stick 1 | B4: 2
A5: Stick 4 | B5: 3
A6: Stick 4 | B6: 4
A7: Stick 5 | B7: 5
A8: Stick 1 | B8: 6
A9: Stick 1 | B9: 6
A10: Stick 5 | B10: 7
A11: Stick 5 | B11: 8
A12: Stick 5 | B12: 9
A13: Stick 4 | B13: 10
A14: Stick 3 | B14: 11
... A16: Stick 4 | B16: 13
B17: 14
A18: Stick 4 | B18: 15
B19: 16
B20: 17
A21: Stick 3 | B21: 18

Sheet Review Coding
A1: light green | B1: review ok in last iteration -> change to white before current review
A2: orange | B2: review nok in last iteration -> to be clarified/fixed -> if clarified/fixed change to yellow again
A3: yellow | B3: review needed, if ok change to light green, if nok change to orange
A4: gray | B4: lines with orphaned FCID, that is no partnumber anymore in this FCID -> we need to discuss if we delete/hide those lines.

Sheet Ressources
A2: Topic | B2: Hyperlink
A3: SDB regions | B3: https://hi-dms.de.bosch.com/docushare/dsweb/ServicesLib/Document-633905/History/
A4: Board-Ids | B4: https://hi-dms.de.bosch.com/docushare/dsweb/Services/Document-454721
A5: System Variant Table | B5: https://hi-dms.de.bosch.com/docushare/dsweb/Get/Document-734406/A-IVI-Variant-Matrix_v01.00_d66.xlsm
A6: Partition table

Sheet SDB vs GN
B2: According to Stefan Weber 26.04.2017 via eMail für Scope2.1:
C3: NAM/MEX | D3: SAM Arg/Chl | E3: Africa/SAF/AUS/NZ | F3: MEA/CA/ISR/IND | G3: EUR/MAG/TURK | H3: RUS | I3: JP/KOR | J3: APAC/TWN/PRC | K3: GOM/THAI/VIET
B4: SDB | C4: SDB_NAM | D4: SDB_LAC | E4: SDB_ASR | F4: SDB_GCC | G4: SDB_EUR | H4: SDB_RUS | I4: SDB_JPN | J4: SDB_PRC | K4: SDB_GOM
B5: Gracenote | C5: 727_NAM | D5: 735_LA | E5: 831 | F5: 731 | G5: 731_EUR | H5: 731 | I5: 831 | J5: 831_734 | K5: 831_734
A7: Scope2: | E7: ASR gibt es nicht | G7: für Australien | J7: 734 only
B10: die ST2.0/ST2.1 Unterscheidung schwirrte mir auch schon durch den Kopf.
B11: ST2.0 hat aktuell noch die alte Aufteilung, da stimmt meine Tabelle natürlich nicht. Da ist PRC à 734 und Australische Ausprägung mit EUR à 831.
A14: Be very carefull changing this mapping table:
A15: It will change the FCID-Table!!!
A16: No_SDB | B16: No_Gracenote
A17: AFR_SDB | B17: 831_AUSKRJPN
A18: CAS_SDB | B18: 731_EUR
A19: DA1_SDB | B19: 734_CN_831_AUSKRJPN
A20: DA2_SDB | B20: 735_LA_831_AUSKRJPN
A21: NAM_SDB | B21: 727_NAM
A22: LAC_SDB | B22: 735_LA
A23: ASR_SDB | B23: 831_AUSKRJPN
A24: GCC_SDB | B24: 731_EUR
A25: EUR_SDB | B25: 731_EUR
A26: EUL_SDB | B26: 731_EUR
A27: RUS_SDB | B27: 731_EUR
... A38: Invalid | B38: Invalid
B40: 734_CN_831_AUSKRJPN_CHENC
B41: 742_JPN_831_AUSKRJPN_CDDB | E41: Only PIVI with 128GB for JPN have CDDB. This is mutual exclusive to "Chenc".

Sheet Legend
A1: Review:
A2: Turn green fields to white
A3: Turn yellow fields to green (if ok) or to orange (if not ok). Add comment for review finding.
A4: Turn orange fields to yellow for next review cycle, if review finding seems to be fixed.
A5: Turn "unfixable" things to red. Possibly an action should follwow to block devices.
A7: Add new lines or change cells:
A8: Turn fields to yellow for review.
A10: Discard full lines for obsolete FCIDs:
A11: Discard line for obsolete part number.
A12: Turn line to grey if no part number is in the line anymore.
A14: Special:
A15: Keep color coding for "RFS as in Manifest"
... A21: Do not use. Entries still in work.
A23: 0.000.000.000-46 | B23: Dummy Entries which might be needed in the future. Should only be introduced if really likely

Sheet Hints
A1: 0488 | B1: New DL-Tooling. PF changed names of Jamplayer config files. Incompatibilty in InitRamFS. USB-Stick-Download will fail. Support for FCIDs >= 00AA (Renault SBX TSB1.BrgP)
A2: 0508 | B2: Support for FCIDs for Nissan TSB6.BrgP. Chenc to Gracenote partition.
A3: 0706 | B3: Support for FCIDs for Nissan TSB6.BrgP. First time support for Board-ID 0x06A3.
A4: 0724 | B4: Support for image-based RFS-Download. Still disabled. First "Compatibility-Jump-Gate" for the time when the feature is enabled. Beginning of RFS-Consolidation.
A5: 0730 | B5: Consolidation of RFS-Names. Obigo implemented but disabled for Renault 16GB-Entry-Nav.
A6: 0514 | B6: Sync with 0730. Removed China-RFS.
A7: 0734 | B7: Support for FCIDs for Nissan TSB7.BrgP. Support for FCIDs for Renault DSB4.Hi. Unfortunately some Board-Ids were not supported by the manifest.xml
A8: 0515 | B8: Support for FCIDs for Nissan TSB7.BrgP. Support for FCIDs for Renault DSB4.Hi.
A9: 0736 | B9: FCIDs for Nissan: TSB8.BrgP, TSB9.BrgP(ST2.0), TSB10.PgP1, TSB11.PgP1, DSB11.1.Hi, DSB11.2.Hi, PP9.PgP1, PP10.PgP1 // Renault: TSB1.BrgP // Sync with N-VM-DS v556 R-VM-DS v199 P-VM-DS v87 // Fixes
A10: 0517 | B10: FCIDs for Nissan: TSB8.BrgP, TSB9.BrgP(ST2.0), TSB10.PgP1, TSB11.PgP1, DSB11.1.Hi, DSB11.2.Hi, PP9.PgP1, PP10.PgP1 // Renault: TSB1.BrgP // Sync with N-VM-DS v556 R-VM-DS v199 P-VM-DS v87 // Fixes
A11: 0744 | B11: Implements new SDB/GCN according to CRQ 0277
A12: 0746 | B12: FCIDs for Nissan PIVI: TSB1.PgP1 (C-Sample)
... A41: <= 2454 | B41: Wrong Partition Schema in FCID 0x01B9. Correction happened in VM without notices.
A43: Kalpuri Sainath (RBEI/ECF2), 03.03.2021:
A44: PF 20.1S: 20.1S2021.07
A45: PF 20.0F/21.0F: BASE_RFS_RCAR3_20.0F30
A46: PF 20.1C: Not yet updated, No Go from Peter Vogel
